Workbook
Name CurMonths: FAR!$P$5
Name PriorMonths: FAR!$P$6

Sheet 사용안내
A1: 이 파일은 계획단계 분석적 검토(FAR) 표준 양식의 비식별 마스터입니다. 원본을 직접 수정하지 말고 사본을 만들어 사용하세요.
A2: ■ 입력 셀은 연한 노란색입니다. 그 외 셀은 수식이므로 덮어쓰지 마세요.
A3: ■ FAR 시트: 당기(회사제시)=G열, 전기=K열, 조정분개 Dr/Cr=H·I열, 질적 판단=Q열.
A4: ■ 기간(개월): FAR 시트 P5(당기), P6(전기)에 입력합니다. 연환산 계산(회전율, 유의성 판정 등)이 이 값을 사용하며, 비어 있으면 Q5에 알림이 표시됩니다.
A5: ■ 전전기 기말 잔액 입력: H451(매출채권), H483(원재료), H494(제품), H505(상품), H517(매입채무).
A6: ■ 회사명은 G5에 입력합니다. 공시 시트의 제목 문구(기수, 기준일 등)는 사용할 때 직접 수정하세요.
A7: ■ 설명란(T열)과 분석 코멘트는 근거가 확인된 사실만 작성하고, 원인이 확인되지 않으면 원인 확인 필요로 표기하세요.
A8: [원본 대비 변경사항]
A9: 1) 회사명, 담당자, 설명 문구, 금액 입력값을 삭제하고 주석(FN)과 분개장 시트를 삭제했습니다.
A10: 2) 반기 고정 산식(/6*12)을 기간(개월) 입력값 기준으로 변경했습니다.
A11: 3) 분석 파트 머리글 날짜를 당기/전기 기준일에 연결하고, 전기 연환산 하드코딩 값(I450, I482, I493, I504)을 수식으로 바꿨습니다.
A12: 4) 공시IS D28, F28(주석 참조 수식)은 삭제하고 비웠습니다.
... A16: 8) 공시IS, 공시CIE, 공시CF 시트의 노란색 셀은 비교표시, 자본변동, 현금흐름 금액 등을 직접 입력하는 칸입니다. 원본의 고객사 금액은 모두 삭제했습니다.

Sheet 공시BS
A1: 재무상태표
A2: 제 33(당) 반기 2024년 06월 30일 현재
A3: 제 32(전) 기 2023년 12월 31일 현재
A4: [회사명]
F5: (단위 : 원)
A6: 과 목 | B6: 주석 | C6: 제 33(당) 반기말 | E6: 제 32(전) 기말
A7: 자산
A8: I. 유동자산 | D8: =SUM(C9:C14) -> 0 | F8: =SUM(E9:E14) -> 0 | H8: =D8=FAR!J14 -> TRUE | I8: =F8=FAR!K14 -> TRUE
A9: 현금 및 현금성자산 | B9: 35,36 | C9: =SUMIF(FAR!C:C,공시BS!A9,FAR!J:J) -> 0 | E9: =SUMIF(FAR!C:C,공시BS!A9,FAR!K:K) -> 0
A10: 매출채권 및 기타채권 | B10: 5,34,35,36 | C10: =SUMIF(FAR!C:C,공시BS!A10,FAR!J:J) -> 0 | E10: =SUMIF(FAR!C:C,공시BS!A10,FAR!K:K) -> 0
A11: 기타유동금융자산 | B11: 6,36 | C11: =SUMIF(FAR!C:C,공시BS!A11,FAR!J:J) -> 0 | E11: =SUMIF(FAR!C:C,공시BS!A11,FAR!K:K) -> 0
A12: 기타유동자산 | B12: 9 | C12: =SUMIF(FAR!C:C,공시BS!A12,FAR!J:J) -> 0 | E12: =SUMIF(FAR!C:C,공시BS!A12,FAR!K:K) -> 0
A13: 재고자산 | B13: 7 | C13: =SUMIF(FAR!C:C,공시BS!A13,FAR!J:J) -> 0 | E13: =SUMIF(FAR!C:C,공시BS!A13,FAR!K:K) -> 0
A14: 당기법인세자산 | B14: 31 | C14: =SUMIF(FAR!C:C,공시BS!A14,FAR!J:J) -> 0 | E14: =SUMIF(FAR!C:C,공시BS!A14,FAR!K:K) -> 0
A15: II. 비유동자산 | D15: =SUM(C16:C22) -> 0 | F15: =SUM(E16:E22) -> 0 | H15: =D15=FAR!J54 -> TRUE | I15: =F15=FAR!K54 -> TRUE
A16: 매출채권 및 기타비유동채권 | B16: 5,34,35,36 | C16: =SUMIF(FAR!C:C,공시BS!A16,FAR!J:J) -> 0 | E16: =SUMIF(FAR!C:C,공시BS!A16,FAR!K:K) -> 0
A17: 장기투자자산 | B17: 8,35,36 | C17: =SUMIF(FAR!C:C,공시BS!A17,FAR!J:J) -> 0 | E17: =SUMIF(FAR!C:C,공시BS!A17,FAR!K:K) -> 0
A18: 종속 및 관계기업투자 | B18: 10 | C18: =SUMIF(FAR!C:C,공시BS!A18,FAR!J:J) -> 0 | E18: =SUMIF(FAR!C:C,공시BS!A18,FAR!K:K) -> 0
A19: 유형자산 | B19: 11,12,14,33 | C19: =SUMIF(FAR!C:C,공시BS!A19,FAR!J:J) -> 0 | E19: =SUMIF(FAR!C:C,공시BS!A19,FAR!K:K) -> 0
A20: 무형자산 | B20: 13 | C20: =SUMIF(FAR!C:C,공시BS!A20,FAR!J:J) -> 0 | E20: =SUMIF(FAR!C:C,공시BS!A20,FAR!K:K) -> 0
A21: 이연법인세자산 | B21: 31 | C21: =SUMIF(FAR!C:C,공시BS!A21,FAR!J:J) -> 0 | E21: =SUMIF(FAR!C:C,공시BS!A21,FAR!K:K) -> 0
A22: 기타비유동자산 | B22: 9 | C22: =SUMIF(FAR!C:C,공시BS!A22,FAR!J:J) -> 0 | E22: =SUMIF(FAR!C:C,공시BS!A22,FAR!K:K) -> 0
A23: 자산총계 | D23: =D8+D15 -> 0 | F23: =F8+F15 -> 0
A24: 부채
A25: I. 유동부채 | D25: =SUM(C26:C30) -> 0 | F25: =SUM(E26:E30) -> 0 | H25: =D25=FAR!J108 -> TRUE | I25: =F25=FAR!K108 -> TRUE
A26: 매입채무 및 기타채무 | B26: 15,19,34,35,36 | C26: =SUMIF(FAR!C:C,공시BS!A26,FAR!J:J) -> 0 | E26: =SUMIF(FAR!C:C,공시BS!A26,FAR!K:K) -> 0
A27: 차입금 | B27: 16,33,35,36 | C27: =SUMIF(FAR!C:C,공시BS!A27,FAR!J:J) -> 0 | E27: =SUMIF(FAR!C:C,공시BS!A27,FAR!K:K) -> 0
A28: 기타유동금융부채 | B28: 17,35,36 | C28: =SUMIF(FAR!C:C,공시BS!A28,FAR!J:J) -> 0 | E28: =SUMIF(FAR!C:C,공시BS!A28,FAR!K:K) -> 0
A29: 기타부채 | B29: 18 | C29: =SUMIF(FAR!C:C,공시BS!A29,FAR!J:J) -> 0 | E29: =SUMIF(FAR!C:C,공시BS!A29,FAR!K:K) -> 0
A30: 유동리스부채 | B30: 14 | C30: =SUMIF(FAR!C:C,공시BS!A30,FAR!J:J) -> 0 | E30: =SUMIF(FAR!C:C,공시BS!A30,FAR!K:K) -> 0
A31: II. 비유동부채 | D31: =SUM(C32:C36) -> 0 | F31: =SUM(E32:E36) -> 0 | H31: =D31=FAR!J146 -> TRUE | I31: =F31=FAR!K146 -> TRUE
A32: 매입채무 및 기타비유동채무 | B32: 15,19,35,36 | C32: =SUMIF(FAR!C:C,공시BS!A32,FAR!J:J) -> 0 | E32: =SUMIF(FAR!C:C,공시BS!A32,FAR!K:K) -> 0
A33: 비유동차입금 | B33: 16,33,35,36 | C33: =SUMIF(FAR!C:C,공시BS!A33,FAR!J:J) -> 0 | E33: =SUMIF(FAR!C:C,공시BS!A33,FAR!K:K) -> 0
A34: 기타비유동금융부채 | B34: 17,35,36 | C34: =SUMIF(FAR!C:C,공시BS!A34,FAR!J:J) -> 0 | E34: =SUMIF(FAR!C:C,공시BS!A34,FAR!K:K) -> 0
A35: 순확정급여부채 | B35: 19 | C35: =SUMIF(FAR!C:C,공시BS!A35,FAR!J:J) -> 0 | E35: =SUMIF(FAR!C:C,공시BS!A35,FAR!K:K) -> 0
A36: 비유동리스부채 | B36: 14 | C36: =SUMIF(FAR!C:C,공시BS!A36,FAR!J:J) -> 0 | E36: =SUMIF(FAR!C:C,공시BS!A36,FAR!K:K) -> 0
A37: 부채총계 | D37: =D25+D31 -> 0 | F37: =F25+F31 -> 0
A38: 자본
A39: I. 자본금 | B39: 20 | D39: =FAR!J179 -> 0 | E39: =SUMIF(FAR!D:D,공시BS!A39,FAR!K:K) -> 0 | F39: =FAR!K179 -> 0
A40: II. 자본잉여금 | B40: 21 | D40: =FAR!J181 -> 0 | F40: =FAR!K181 -> 0
...

Sheet 공시IS
A1: 포괄손익계산서
A2: 제 33(당) 반기 2024년 1월 1일부터 2024년 06월 30일까지
A3: 제 32(전) 반기 2023년 1월 1일부터 2023년 06월 30일까지
A4: =공시BS!A4 -> [회사명]
F5: (단위 : 원)
A6: 과 목 | B6: 주석 | C6: 제 33(당) 반기 | E6: 제 32(전) 반기 | K6: 1분기 | L6: 3개월 | M6: 누적
A7: I. 매출액 | B7: 4,24,34 | D7: =SUMIF(FAR!C:C,공시IS!A7,FAR!J:J) -> 0 | F7: =SUMIF(FAR!C:C,공시IS!A7,FAR!K:K) -> 0 | L7: =M7-K7 -> 0 | M7: =D7 -> 0
A8: II.매출원가 | B8: 7,25,26 | D8: =SUMIF(FAR!C:C,공시IS!A8,FAR!J:J) -> 0 | F8: =SUMIF(FAR!C:C,공시IS!A8,FAR!K:K) -> 0 | L8: =M8-K8 -> 0 | M8: =D8 -> 0
A9: III. 매출총이익 | D9: =D7-D8 -> 0 | F9: =F7-F8 -> 0 | L9: =M9-K9 -> 0 | M9: =M7-M8 -> 0
A10: 판매비와관리비 | B10: 25,27,34 | D10: =SUMIF(FAR!C:C,공시IS!A10,FAR!J:J) -> 0 | F10: =SUMIF(FAR!C:C,공시IS!A10,FAR!K:K) -> 0 | L10: =M10-K10 -> 0 | M10: =D10 -> 0
A11: IV.영업이익 | D11: =D9-D10 -> 0 | F11: =F9-F10 -> 0 | H11: =D11=FAR!J259 -> TRUE | J11: =F11=FAR!K259 -> TRUE | L11: =M11-K11 -> 0 | M11: =M9-M10 -> 0
A12: 금융수익 | B12: 29,35 | C12: =SUMIF(FAR!C:C,공시IS!A12,FAR!J:J) -> 0 | L12: =M12-K12 -> 0 | M12: =C12 -> 0
A13: 금융비용 | B13: 29,35 | C13: =SUMIF(FAR!C:C,공시IS!A13,FAR!J:J) -> 0 | L13: =M13-K13 -> 0 | M13: =C13 -> 0
A14: 기타수익 | B14: 28 | C14: =SUMIF(FAR!C:C,공시IS!A14,FAR!J:J) -> 0 | E14: =SUMIF(FAR!C:C,공시IS!A14,FAR!K:K) -> 0 | L14: =M14-K14 -> 0 | M14: =C14 -> 0
A15: 기타비용 | B15: 28 | C15: =SUMIF(FAR!C:C,공시IS!A15,FAR!J:J) -> 0 | E15: =SUMIF(FAR!C:C,공시IS!A15,FAR!K:K) -> 0 | L15: =M15-K15 -> 0 | M15: =C15 -> 0
A16: 종속기업및관계기업투자주식관련손익 | B16: 10,30 | C16: =SUMIF(FAR!C:C,공시IS!A16,FAR!J:J) -> 0 | L16: =M16-K16 -> 0 | M16: =C16 -> 0
A17: V. 법인세차감전순이익 | D17: =D11+C12-C13+C14-C15+C16 -> 0 | F17: =F11+E12-E13+E14-E15+E16 -> 0 | H17: =D17=FAR!J315 -> TRUE | J17: =F17=FAR!K315 -> TRUE | K17: =K11+K12+K14+K16-K13-K15 -> 0 | L17: =M17-K17 -> 0 | M17: =M11+M12+M14+M16-M13-M15 -> 0
A18: VI. 법인세비용 | B18: 31 | D18: =SUMIF(FAR!C:C,공시IS!A18,FAR!J:J) -> 0 | F18: =SUMIF(FAR!C:C,공시IS!A18,FAR!K:K) -> 0 | L18: =M18-K18 -> 0 | M18: =D18 -> 0
A19: VII. 당기순이익 | D19: =D17-D18 -> 0 | F19: =F17-F18 -> 0 | H19: =D19=FAR!J318 -> TRUE | J19: =F19=FAR!K318 -> TRUE | K19: =K17-K18 -> 0 | L19: =M19-K19 -> 0 | M19: =M17-M18 -> 0
A20: VIII. 기타포괄손익 | D20: =D23+D21 -> 0 | F20: =F23+F21 -> 0 | K20: =K23+K21 -> 0 | L20: =M20-K20 -> 0 | M20: =M21+M23 -> 0
A21: 후속기간에당기손익으로 재분류되는 포괄손익 | D21: =SUM(C22:C22) -> 0 | F21: =SUM(E22:E22) -> 0 | K21: =K22 -> 0 | L21: =M21-K21 -> 0 | M21: =M22 -> 0
A22: 지분법 자본변동 | B22: 10,22 | C22: =SUMIF(FAR!C:C,공시IS!A22,FAR!J:J) -> 0 | E22: =SUMIF(FAR!C:C,공시IS!A22,FAR!K:K) -> 0 | L22: =M22-K22 -> 0 | M22: =C22 -> 0
A23: 후속기간에당기손익으로 재분류되지 않는 포괄손익 | D23: =SUM(C24:C25) -> 0 | F23: =SUM(E24:E25) -> 0 | K23: =SUM(K24:K25) -> 0 | L23: =M23-K23 -> 0 | M23: =SUM(M24:M25) -> 0
A24: 확정급여제도의 재측정요소 | B24: 19 | C24: =SUMIF(FAR!C:C,공시IS!A24,FAR!J:J) -> 0 | L24: =M24-K24 -> 0 | M24: =C24 -> 0
A25: 지분법자본변동 이익잉여금 | B25: 10,23 | C25: =SUMIF(FAR!C:C,공시IS!A25,FAR!J:J) -> 0 | L25: =M25-K25 -> 0 | M25: =C25 -> 0
A26: IX. 총포괄이익 | D26: =D19+D20 -> 0 | F26: =F19+F20 -> 0 | H26: =D26=FAR!J328 -> TRUE | J26: =F26=FAR!K328 -> TRUE | K26: =K19+K20 -> 0 | L26: =L19+L20 -> 0 | M26: =M19+M20 -> 0
A27: X. 주당이익 | B27: (주33)
A28: 기본주당이익 | L28: =M28-K28 -> 0 | M28: =D28 -> 0
D30: =D18/D17 -> #DIV/0! | F30: =F18/F17 -> #DIV/0!

Sheet 공시CIE
A1: 자본변동표
A2: =공시IS!A2 -> 제 33(당) 반기 2024년 1월 1일부터 2024년 06월 30일까지
A3: =공시IS!A3 -> 제 32(전) 반기 2023년 1월 1일부터 2023년 06월 30일까지
A4: =공시IS!A4 -> [회사명]
G5: (단위 : 원)
A6: 과 목 | B6: 자 본 금 | C6: 자본잉여금 | D6: 기타자본 | E6: 기타포괄손익누계액 | F6: 이익잉여금(결손금) | G6: 총 계
A7: 2023.01.01(전기초)
A8: 전기 오류 수정 | G8: =SUM(B8:F8) -> 0
A9: 2023.01.01(전기초) (조정후) | B9: =SUM(B7:B8) -> 0 | C9: =SUM(C7:C8) -> 0 | D9: =SUM(D7:D8) -> 0 | E9: =SUM(E7:E8) -> 0 | F9: =SUM(F7:F8) -> 0 | G9: =SUM(G7:G8) -> 0
A10: 반기순이익 | F10: =공시IS!F19 -> 0 | G10: =SUM(B10:F10) -> 0
A11: 기타포괄손익
A12: 지분법자본변동 | G12: =SUM(B12:F12) -> 0
A13: 지분법자본변동 이익잉여금 | G13: =SUM(B13:F13) -> 0
A14: 확정급여제도의 재측정손익 | F14: =공시IS!E24 -> 0 | G14: =SUM(B14:F14) -> 0
A15: 총포괄이익 | B15: =SUM(B10+B11) -> 0 | C15: =SUM(C10+C11) -> 0 | D15: =SUM(D10+D11) -> 0 | E15: =E10+SUM(E12:E14) -> 0 | F15: =F10+SUM(F12:F14) -> 0 | G15: =G10+SUM(G12:G14) -> 0
A16: 자본에 직접 반영된 주주와의 거래 | G16: =SUM(B16:F16) -> 0
A17: 배당금의지급 | G17: =SUM(B17:F17) -> 0
A18: 주식선택권의 소멸 | G18: =SUM(B18:F18) -> 0
A19: 2023.06.30(전반기말) | B19: =B9+B15+B17+B18 -> 0 | C19: =C9+C15+C17+C18 -> 0 | D19: =D9+D15+D17+D18 -> 0 | E19: =E9+E15+E17+E18 -> 0 | F19: =F9+F15+F17+F18 -> 0 | G19: =G9+G15+G17+G18 -> 0
A20: 2024.01.01(당기초) | G20: =SUM(B20:F20) -> 0
A21: 반기순이익 | F21: =공시IS!D19 -> 0 | G21: =SUM(B21:F21) -> 0
A22: 기타포괄손익 | G22: =SUM(B22:F22) -> 0
A23: 지분법자본변동 | E23: =공시IS!C22 -> 0 | G23: =SUM(B23:F23) -> 0
A24: 확정급여제도의 재측정요소 | F24: =공시IS!C24 -> 0 | G24: =SUM(B24:F24) -> 0
A25: 지분법이익잉여금 변동 | F25: =공시IS!C25 -> 0
A26: 총포괄이익 | B26: =B21+SUM(B23:B25) -> 0 | C26: =C21+SUM(C23:C25) -> 0 | D26: =D21+SUM(D23:D25) -> 0 | E26: =E21+SUM(E23:E25) -> 0 | F26: =F21+SUM(F23:F25) -> 0 | G26: =SUM(B26:F26) -> 0
A27: 자본에 직접 반영된 주주와의 거래 | G27: =SUM(B27:F27) -> 0
A28: 연차배당 | G28: =SUM(B28:F28) -> 0
A29: 사업양수도 | G29: =SUM(B29:F29) -> 0
A30: 2023.06.30(당반기말) | B30: =B20+B26+B27 -> 0 | C30: =C20+C26+C27 -> 0 | D30: =D20+D26+D27 -> 0 | E30: =E20+E26+E27 -> 0 | F30: =F20+F26+F27 -> 0 | G30: =G20+G26+G27 -> 0
B31: =B30=공시BS!D39 -> TRUE | C31: =C30=공시BS!D40 -> TRUE | D31: =D30=공시BS!D41 -> TRUE | E31: =E30=공시BS!D42 -> TRUE | F31: =F30=공시BS!D43 -> TRUE | G31: =G30=공시BS!D44 -> TRUE

Sheet 공시CF
B1: 현 금 흐 름 표
B3: =공시CIE!A2 -> 제 33(당) 반기 2024년 1월 1일부터 2024년 06월 30일까지
B4: =공시CIE!A3 -> 제 32(전) 반기 2023년 1월 1일부터 2023년 06월 30일까지
F6: (단위 : 원)
B7: 과 목 | C7: 제 34(당) 반기 | E7: 제 33(전) 반기
B8: I.영업활동으로 인한 현금흐름 | D8: =SUM(C9:C13) -> 0 | F8: =SUM(E9:E13) -> 0
B9: 1. 영업에서 창출된 현금흐름
B10: 2. 이자의 수취
B11: 3. 이자의 지급
B12: 4. 법인세의 납부
B13: 5. 배당금 수취
B14: II.투자활동으로 인한 현금흐름 | D14: =C15+C28 -> 0 | F14: =E15+E28 -> 0
B15: 1. 투자활동으로 인한 현금유입액 | C15: =SUM(C16:C27) -> 0 | E15: =SUM(E16:E27) -> 0
B16: 단기대여금의 감소
B17: 기타유동금융자산의 감소
B18: 장기대여금의 감소
B19: 매도가능금융자산의 처분
B20: 장기투자자산의 처분
B21: 유형자산의 처분
B22: 정부보조금의 수령
B23: 임대보증금의 수령
B24: 사업결합에 따른 순현금흐름
B25: 보증금의 회수
B26: 종속기업주식의 처분
B27: 관계기업주식의 처분
B28: 2. 투자활동으로 인한 현금유출액 | C28: =-SUM(C29:C41) -> 0 | E28: =-SUM(E29:E41) -> 0
B29: 단기대여금의 증가
B30: 기타유동금융자산의 취득
B31: 장기대여금의 증가
B32: 장기금융상품의 취득
B33: 매도가능금융자산의 취득
B34: 만기보유금융자산의 취득
B35: 장기투자자산의 취득
B36: 유형자산의 취득
B37: 무형자산의 취득
B38: 사업분할에 따른 순현금흐름
B39: 보증금의 증가
B40: 종속기업주식의 취득
B41: 관계기업주식의 취득
B42: III.재무활동으로인한현금흐름 | D42: =C43+C50 -> 0 | F42: =E43+E50 -> 0
...

Sheet 왜곡표시
M1: 회사로부터 제시받은 왜곡표시
B2: 회사명: | E2: [회사명] | H2: 작성자: | J2: 일자:
B3: 결산일: | H3: 검토자:
B5: Description | G5: BS | I5: IS | K5: 손익에 미치는 효과 | L5: Accep -ted | M5: Pass -ed
G6: Dr) | H6: Cr) | I6: Dr) | J6: Cr)
B62: 수정사항 효과 합계 | G62: =SUM(G7:G61) -> 0 | H62: =SUM(H7:H61) -> 0 | I62: =SUM(I7:I61) -> 0 | J62: =SUM(J7:J61) -> 0 | K62: =SUM(K7:K61) -> 0 | O62: =G62+I62=H62+J62 -> TRUE
K63: =FAR!I329-FAR!H329=K62 -> TRUE
F65: 왜곡표시 | G65: =G62+I62 -> 0 | H65: =H62+J62 -> 0
F66: 정산표 | G66: =FAR!H202 -> 0 | H66: =FAR!I202 -> 0
F67: diff | G67: =G65-G66 -> 0 | H67: =H65-H66 -> 0

Sheet FAR
D2: 계획단계 분석적절차 - Planning Analytical Review
F4: BDO
F5: CLIENT NAME | G5: [회사명] | K5: Preparer | L5: Reviewer | M5: Date | O5: 당기 기간(개월) | Q5: =IF(AND(ISNUMBER(P5),ISNUMBER(P6)),"","※ 기간(개월) 입력 필요 (Q5, Q6)") -> ※ 기간(개월) 입력 필요 (Q5, Q6)
F6: DOCUMENT NAME | G6: Planning Analytical Review | O6: 전기 기간(개월)
F7: PERIOD END | K7: Engagement Materiality | L7: Performance Materiality | M7: Currency
F8: DOCUMENT MANAGER REF | K8: =ROUND(G207*0.5%,-6) -> 0 | L8: =K8*75% -> 0 | M8: No Rounding
D10: 1. 재무상태표
G11: 당기(회사제시) | H11: Dr | I11: Cr | J11: 당기(검토후제시) | K11: 전기 | L11: Variance | N11: 중요성 양정기준 | O11: 유의중요성 x 75% | P11: 유의한 계정과목 | S11: 설명
J12: =G12 -> 0 | L12: 금액 | M12: % | N12: =K8 -> 0 | O12: =N12*75% -> 0 | P12: 양적 | Q12: 질적 | R12: 여부 결론
A13: 1 | D13: 재무상태표
A14: 1 | B14: Assign | C14: 공시계정 | D14: Ⅰ.유동자산 | G14: =G15+G18+G28+G37+G40+G52 -> 0 | J14: =J15+J18+J28+J37+J40+J52 -> 0 | K14: =K15+K18+K28+K37+K40+K52 -> 0 | L14: =L15+L18+L28+L37+L40+L52 -> 0 | M14: =L14/K14 -> #DIV/0!
E15: (1)현금및현금성자산 | G15: =SUM(G16:G17) -> 0 | J15: =SUM(J16:J17) -> 0 | K15: =SUM(K16:K17) -> 0 | L15: =SUM(L16:L17) -> 0 | M15: =L15/K15 -> #DIV/0!
A16: 1 | C16: 현금 및 현금성자산 | F16: 현금 | J16: =G16+H16-I16 -> 0 | L16: =J16-K16 -> 0 | M16: =L16/K16 -> #DIV/0! | N16: =G16/$N$12 -> #DIV/0! | O16: =G16/$O$12 -> #DIV/0! | P16: =IF(ABS(O16)>100%,"O","X") -> #DIV/0! | R16: =IF(P16="O","O",IF(Q16="O","O","X")) -> #DIV/0!
C17: 현금 및 현금성자산 | F17: 현금성자산 | J17: =G17+H17-I17 -> 0 | L17: =J17-K17 -> 0 | M17: =L17/K17 -> #DIV/0! | N17: =G17/$N$12 -> #DIV/0! | O17: =G17/$O$12 -> #DIV/0! | P17: =IF(ABS(O17)>100%,"O","X") -> #DIV/0! | R17: =IF(P17="O","O",IF(Q17="O","O","X")) -> #DIV/0!
E18: (2)매출채권및기타유동채권 | G18: =SUM(G19:G27) -> 0 | J18: =SUM(J19:J27) -> 0 | K18: =SUM(K19:K27) -> 0 | L18: =SUM(L19:L27) -> 0 | M18: =L18/K18 -> #DIV/0!
C19: 매출채권 및 기타채권 | F19: 매출채권 | J19: =G19+H19-I19 -> 0 | L19: =J19-K19 -> 0 | M19: =L19/K19 -> #DIV/0! | N19: =G19/$N$12 -> #DIV/0! | O19: =G19/$O$12 -> #DIV/0! | P19: =IF(ABS(O19)>100%,"O","X") -> #DIV/0! | R19: =IF(P19="O","O",IF(Q19="O","O","X")) -> #DIV/0!
C20: 매출채권 및 기타채권 | F20: 대손충당금 | J20: =G20+H20-I20 -> 0 | L20: =J20-K20 -> 0 | M20: =L20/K20 -> #DIV/0! | N20: =G20/$N$12 -> #DIV/0! | O20: =G20/$O$12 -> #DIV/0! | P20: =IF(ABS(O20)>100%,"O","X") -> #DIV/0! | R20: =IF(P20="O","O",IF(Q20="O","O","X")) -> #DIV/0!
C21: 매출채권 및 기타채권 | F21: 미수금 | J21: =G21+H21-I21 -> 0 | L21: =J21-K21 -> 0 | M21: =L21/K21 -> #DIV/0! | N21: =G21/$N$12 -> #DIV/0! | O21: =G21/$O$12 -> #DIV/0! | P21: =IF(ABS(O21)>100%,"O","X") -> #DIV/0! | R21: =IF(P21="O","O",IF(Q21="O","O","X")) -> #DIV/0!
A22: 1 | C22: 매출채권 및 기타채권 | F22: 대손충당금 | J22: =G22+H22-I22 -> 0 | L22: =J22-K22 -> 0 | M22: =L22/K22 -> #DIV/0! | N22: =G22/$N$12 -> #DIV/0! | O22: =G22/$O$12 -> #DIV/0! | P22: =IF(ABS(O22)>100%,"O","X") -> #DIV/0! | R22: =IF(P22="O","O",IF(Q22="O","O","X")) -> #DIV/0!
C23: 매출채권 및 기타채권 | F23: 미수금_국고보조금 | J23: =G23+H23-I23 -> 0 | L23: =J23-K23 -> 0 | M23: =L23/K23 -> #DIV/0! | N23: =G23/$N$12 -> #DIV/0! | O23: =G23/$O$12 -> #DIV/0! | P23: =IF(ABS(O23)>100%,"O","X") -> #DIV/0! | R23: =IF(P23="O","O",IF(Q23="O","O","X")) -> #DIV/0!
A24: 1 | C24: 매출채권 및 기타채권 | F24: 미수수익 | J24: =G24+H24-I24 -> 0 | L24: =J24-K24 -> 0 | M24: =L24/K24 -> #DIV/0! | N24: =G24/$N$12 -> #DIV/0! | O24: =G24/$O$12 -> #DIV/0! | P24: =IF(ABS(O24)>100%,"O","X") -> #DIV/0! | R24: =IF(P24="O","O",IF(Q24="O","O","X")) -> #DIV/0!
C25: 매출채권 및 기타채권 | F25: 대손충당금 | J25: =G25+H25-I25 -> 0 | L25: =J25-K25 -> 0 | M25: =L25/K25 -> #DIV/0! | N25: =G25/$N$12 -> #DIV/0! | O25: =G25/$O$12 -> #DIV/0! | P25: =IF(ABS(O25)>100%,"O","X") -> #DIV/0! | R25: =IF(P25="O","O",IF(Q25="O","O","X")) -> #DIV/0!
C26: 매출채권 및 기타채권 | F26: 단기대여금및수취채권 | J26: =G26+H26-I26 -> 0 | L26: =J26-K26 -> 0 | M26: =L26/K26 -> #DIV/0! | N26: =G26/$N$12 -> #DIV/0! | O26: =G26/$O$12 -> #DIV/0! | P26: =IF(ABS(O26)>100%,"O","X") -> #DIV/0! | R26: =IF(P26="O","O",IF(Q26="O","O","X")) -> #DIV/0!
C27: 매출채권 및 기타채권 | F27: 대손충당금 | J27: =G27+H27-I27 -> 0 | L27: =J27-K27 -> 0 | M27: =L27/K27 -> #DIV/0! | N27: =G27/$N$12 -> #DIV/0! | O27: =G27/$O$12 -> #DIV/0! | P27: =IF(ABS(O27)>100%,"O","X") -> #DIV/0! | R27: =IF(P27="O","O",IF(Q27="O","O","X")) -> #DIV/0!
E28: (3)기타유동자산 | G28: =SUM(G29:G36) -> 0 | J28: =SUM(J29:J36) -> 0 | K28: =SUM(K29:K36) -> 0 | L28: =SUM(L29:L36) -> 0 | M28: =L28/K28 -> #DIV/0! | N28: =G28/$N$12 -> #DIV/0! | O28: =G28/$O$12 -> #DIV/0! | P28: =IF(ABS(O28)>100%,"O","X") -> #DIV/0! | R28: =IF(P28="O","O",IF(Q28="O","O","X")) -> #DIV/0!
C29: 기타유동자산 | F29: 선급금 | J29: =G29+H29-I29 -> 0 | L29: =J29-K29 -> 0 | M29: =L29/K29 -> #DIV/0! | N29: =G29/$N$12 -> #DIV/0! | O29: =G29/$O$12 -> #DIV/0! | P29: =IF(ABS(O29)>100%,"O","X") -> #DIV/0! | R29: =IF(P29="O","O",IF(Q29="O","O","X")) -> #DIV/0!
A30: 1 | C30: 기타유동자산 | F30: 대손충당금 | J30: =G30+H30-I30 -> 0 | L30: =J30-K30 -> 0 | M30: =L30/K30 -> #DIV/0! | N30: =G30/$N$12 -> #DIV/0! | O30: =G30/$O$12 -> #DIV/0! | P30: =IF(ABS(O30)>100%,"O","X") -> #DIV/0! | R30: =IF(P30="O","O",IF(Q30="O","O","X")) -> #DIV/0!
C31: 기타유동자산 | F31: 가지급금 | J31: =G31+H31-I31 -> 0 | L31: =J31-K31 -> 0 | M31: =L31/K31 -> #DIV/0! | N31: =G31/$N$12 -> #DIV/0! | O31: =G31/$O$12 -> #DIV/0! | P31: =IF(ABS(O31)>100%,"O","X") -> #DIV/0! | R31: =IF(P31="O","O",IF(Q31="O","O","X")) -> #DIV/0!
C32: 당기법인세자산 | F32: 선급법인세 | J32: =G32+H32-I32 -> 0 | L32: =J32-K32 -> 0 | M32: =L32/K32 -> #DIV/0! | N32: =G32/$N$12 -> #DIV/0! | O32: =G32/$O$12 -> #DIV/0! | P32: =IF(ABS(O32)>100%,"O","X") -> #DIV/0! | R32: =IF(P32="O","O",IF(Q32="O","O","X")) -> #DIV/0!
A33: 1 | C33: 기타유동자산 | F33: 선급비용 | J33: =G33+H33-I33 -> 0 | L33: =J33-K33 -> 0 | M33: =L33/K33 -> #DIV/0! | N33: =G33/$N$12 -> #DIV/0! | O33: =G33/$O$12 -> #DIV/0! | P33: =IF(ABS(O33)>100%,"O","X") -> #DIV/0! | R33: =IF(P33="O","O",IF(Q33="O","O","X")) -> #DIV/0!
C34: 기타유동자산 | F34: 부가세환급금 | J34: =G34+H34-I34 -> 0 | L34: =J34-K34 -> 0 | M34: =L34/K34 -> #DIV/0! | N34: =G34/$N$12 -> #DIV/0! | O34: =G34/$O$12 -> #DIV/0! | P34: =IF(ABS(O34)>100%,"O","X") -> #DIV/0! | R34: =IF(P34="O","O",IF(Q34="O","O","X")) -> #DIV/0!
C35: 기타유동자산 | F35: 반품회수권자산 | J35: =G35+H35-I35 -> 0 | L35: =J35-K35 -> 0 | M35: =L35/K35 -> #DIV/0! | N35: =G35/$N$12 -> #DIV/0! | O35: =G35/$O$12 -> #DIV/0! | P35: =IF(ABS(O35)>100%,"O","X") -> #DIV/0! | R35: =IF(P35="O","O",IF(Q35="O","O","X")) -> #DIV/0!
A36: 1 | C36: 기타유동자산 | F36: 부가세대급금 | J36: =G36+H36-I36 -> 0 | L36: =J36-K36 -> 0 | M36: =L36/K36 -> #DIV/0! | N36: =G36/$N$12 -> #DIV/0! | O36: =G36/$O$12 -> #DIV/0! | P36: =IF(ABS(O36)>100%,"O","X") -> #DIV/0! | R36: =IF(P36="O","O",IF(Q36="O","O","X")) -> #DIV/0!
A37: 1 | E37: (4)기타유동금융자산 | G37: =SUM(G38:G39) -> 0 | J37: =SUM(J38:J39) -> 0 | K37: =SUM(K38:K39) -> 0 | L37: =SUM(L38:L39) -> 0 | M37: =L37/K37 -> #DIV/0! | N37: =G37/$N$12 -> #DIV/0! | O37: =G37/$O$12 -> #DIV/0! | P37: =IF(ABS(O37)>100%,"O","X") -> #DIV/0! | Q37: O | R37: =IF(P37="O","O",IF(Q37="O","O","X")) -> #DIV/0!
C38: 기타유동금융자산 | F38: 파생상품자산 | J38: =G38+H38-I38 -> 0 | L38: =J38-K38 -> 0 | M38: =L38/K38 -> #DIV/0! | N38: =G38/$N$12 -> #DIV/0! | O38: =G38/$O$12 -> #DIV/0! | P38: =IF(ABS(O38)>100%,"O","X") -> #DIV/0! | R38: =IF(P38="O","O",IF(Q38="O","O","X")) -> #DIV/0!
A39: 1 | C39: 기타유동금융자산 | F39: 단기금융상품 | J39: =G39+H39-I39 -> 0 | L39: =J39-K39 -> 0 | M39: =L39/K39 -> #DIV/0! | N39: =G39/$N$12 -> #DIV/0! | O39: =G39/$O$12 -> #DIV/0! | P39: =IF(ABS(O39)>100%,"O","X") -> #DIV/0! | R39: =IF(P39="O","O",IF(Q39="O","O","X")) -> #DIV/0!
E40: (5)재고자산 | G40: =SUM(G41:G51) -> 0 | J40: =SUM(J41:J51) -> 0 | K40: =SUM(K41:K51) -> 0 | L40: =SUM(L41:L51) -> 0 | M40: =L40/K40 -> #DIV/0! | N40: =G40/$N$12 -> #DIV/0! | O40: =G40/$O$12 -> #DIV/0! | P40: =IF(ABS(O40)>100%,"O","X") -> #DIV/0! | R40: =IF(P40="O","O",IF(Q40="O","O","X")) -> #DIV/0!
C41: 재고자산 | F41: 상품 | J41: =G41+H41-I41 -> 0 | L41: =J41-K41 -> 0 | M41: =L41/K41 -> #DIV/0! | N41: =G41/$N$12 -> #DIV/0! | O41: =G41/$O$12 -> #DIV/0! | P41: =IF(ABS(O41)>100%,"O","X") -> #DIV/0! | R41: =IF(P41="O","O",IF(Q41="O","O","X")) -> #DIV/0!
C42: 재고자산 | F42: 상품평가충당금 | J42: =G42+H42-I42 -> 0 | L42: =J42-K42 -> 0 | M42: =L42/K42 -> #DIV/0! | N42: =G42/$N$12 -> #DIV/0! | O42: =G42/$O$12 -> #DIV/0! | P42: =IF(ABS(O42)>100%,"O","X") -> #DIV/0! | R42: =IF(P42="O","O",IF(Q42="O","O","X")) -> #DIV/0!
C43: 재고자산 | F43: 제품 | J43: =G43+H43-I43 -> 0 | L43: =J43-K43 -> 0 | M43: =L43/K43 -> #DIV/0! | N43: =G43/$N$12 -> #DIV/0! | O43: =G43/$O$12 -> #DIV/0! | P43: =IF(ABS(O43)>100%,"O","X") -> #DIV/0! | R43: =IF(P43="O","O",IF(Q43="O","O","X")) -> #DIV/0!
...
