Workbook
Name CurMonths: FAR!$P$5
Name PriorMonths: FAR!$P$6

Sheet 사용안내
A1: 이 파일은 일반기업회계기준(K-GAAP) 회사용 계획단계 분석적 검토(FAR) 표준 양식의 비식별 마스터입니다. 원본을 직접 수정하지 말고 사본을 만들어 사용하세요.
A2: ■ 입력 셀은 연한 노란색입니다. 그 외 셀은 수식이므로 덮어쓰지 마세요.
A3: ■ FAR 시트: 당기(회사제시)=G열, 전기=K열, 조정분개 Dr/Cr=H·I열, 질적 판단=Q열. 계정과목은 회사 재무제표의 이름을 그대로 G열에 적습니다.
A4: ■ 계정 행 추가/삭제: 각 그룹(당좌자산, 재고자산 등)의 계정 행은 회사에 맞게 추가·삭제합니다. 그룹 안쪽에 행을 삽입하면 소계·분석 수식이 자동으로 따라갑니다. 분석 파트가 참조하는 계정(매출채권, 대손충당금, 재고자산 구성, 매입채무 등)은 행을 지우지 말고 금액을 0으로 두세요.
A5: ■ 부호: 대손충당금, 감가상각누계액, 자기주식, 기말재고액, 매출할인처럼 차감 성격 계정은 음수로 입력합니다. 부채·자본·수익 행은 대변 증가 기준으로 계산됩니다.
A6: ■ 기간(개월): FAR 시트 P5(당기), P6(전기)에 입력합니다. 연환산 계산이 이 값을 사용하며, 비어 있으면 Q5에 알림이 표시됩니다.
A7: ■ 전전기 기말 잔액 입력: 분석 파트(매출채권, 원재료, 제품, 상품, 매입채무)의 노란색 기초 잔액 셀에 입력합니다.
A8: ■ 공시BS, 공시IS 시트는 FAR의 행 구조에서 생성된 것입니다. FAR에 계정 행을 추가하면 공시 시트도 다시 생성해야 합니다.
A9: ■ 설명란(S열)과 분석 코멘트는 근거가 확인된 사실만 작성하고, 원인이 확인되지 않으면 원인 확인 필요로 표기하세요.
A10: [이 양식의 특징]
A11: 1) K-IFRS 양식(FAR)과 같은 열 구성과 분석 구성(비율분석, 매출, 매출원가, 판관비, 매출채권, 재고자산, 매입채무)을 사용합니다.
A12: 2) 계정과목 열 머리글은 공시계정이며, 일반기업회계기준 회사는 재무제표의 계정과목을 그대로 사용합니다.
... A16: 6) 구조 변경 이력: 원본(K-IFRS) 양식의 반기 고정 산식은 기간(개월) 입력값 기준으로, 차변 성격은 H+I-J, 대변 성격은 H+J-I로 통일했습니다.

Sheet 공시BS
A1: 재무상태표
A2: 제 [ ](당) 기 [ ]년 [ ]월 [ ]일 현재
A3: 제 [ ](전) 기 [ ]년 [ ]월 [ ]일 현재
A4: [회사명]
F5: (단위 : 원)
A6: 과 목 | B6: 주석 | C6: 당기 | E6: 전기
A7: 자산
A8: Ⅰ.유동자산 | D8: =D9+D25 -> 0 | F8: =F9+F25 -> 0 | H8: =D8=FAR!J14 -> TRUE | I8: =F8=FAR!K14 -> TRUE
A9: 1.당좌자산 | D9: =SUM(C10:C24) -> 0 | F9: =SUM(E10:E24) -> 0 | H9: =D9=FAR!J15 -> TRUE | I9: =F9=FAR!K15 -> TRUE
A10: 현금및현금성자산 | C10: =FAR!J16 -> 0 | E10: =FAR!K16 -> 0
A11: 단기금융상품 | C11: =FAR!J17 -> 0 | E11: =FAR!K17 -> 0
A12: 단기투자증권 | C12: =FAR!J18 -> 0 | E12: =FAR!K18 -> 0
A13: 매출채권 | C13: =FAR!J19 -> 0 | E13: =FAR!K19 -> 0
A14: 대손충당금(매출채권) | C14: =FAR!J20 -> 0 | E14: =FAR!K20 -> 0
A15: 미수금 | C15: =FAR!J21 -> 0 | E15: =FAR!K21 -> 0
A16: 대손충당금(미수금) | C16: =FAR!J22 -> 0 | E16: =FAR!K22 -> 0
A17: 미수수익 | C17: =FAR!J23 -> 0 | E17: =FAR!K23 -> 0
A18: 선급금 | C18: =FAR!J24 -> 0 | E18: =FAR!K24 -> 0
A19: 선급비용 | C19: =FAR!J25 -> 0 | E19: =FAR!K25 -> 0
A20: 선납세금 | C20: =FAR!J26 -> 0 | E20: =FAR!K26 -> 0
A21: 부가세대급금 | C21: =FAR!J27 -> 0 | E21: =FAR!K27 -> 0
... A24: 기타당좌자산 | C24: =FAR!J30 -> 0 | E24: =FAR!K30 -> 0
A25: 2.재고자산 | D25: =SUM(C26:C34) -> 0 | F25: =SUM(E26:E34) -> 0 | H25: =D25=FAR!J31 -> TRUE | I25: =F25=FAR!K31 -> TRUE
A26: 상품 | C26: =FAR!J32 -> 0 | E26: =FAR!K32 -> 0
A27: 평가충당금(상품) | C27: =FAR!J33 -> 0 | E27: =FAR!K33 -> 0
A28: 제품 | C28: =FAR!J34 -> 0 | E28: =FAR!K34 -> 0
A29: 평가충당금(제품) | C29: =FAR!J35 -> 0 | E29: =FAR!K35 -> 0
A30: 재공품 | C30: =FAR!J36 -> 0 | E30: =FAR!K36 -> 0
A31: 평가충당금(재공품) | C31: =FAR!J37 -> 0 | E31: =FAR!K37 -> 0
A32: 원재료 | C32: =FAR!J38 -> 0 | E32: =FAR!K38 -> 0
A33: 평가충당금(원재료) | C33: =FAR!J39 -> 0 | E33: =FAR!K39 -> 0
A34: 기타재고자산 | C34: =FAR!J40 -> 0 | E34: =FAR!K40 -> 0
A35: Ⅱ.비유동자산 | D35: =D36+D44+D60+D65 -> 0 | F35: =F36+F44+F60+F65 -> 0 | H35: =D35=FAR!J41 -> TRUE | I35: =F35=FAR!K41 -> TRUE
A36: 1.투자자산 | D36: =SUM(C37:C43) -> 0 | F36: =SUM(E37:E43) -> 0 | H36: =D36=FAR!J42 -> TRUE | I36: =F36=FAR!K42 -> TRUE
A37: 장기금융상품 | C37: =FAR!J43 -> 0 | E37: =FAR!K43 -> 0
A38: 장기투자증권 | C38: =FAR!J44 -> 0 | E38: =FAR!K44 -> 0
A39: 지분법적용투자주식 | C39: =FAR!J45 -> 0 | E39: =FAR!K45 -> 0
A40: 장기대여금 | C40: =FAR!J46 -> 0 | E40: =FAR!K46 -> 0
A41: 대손충당금(장기대여금) | C41: =FAR!J47 -> 0 | E41: =FAR!K47 -> 0
A42: 퇴직보험예치금 | C42: =FAR!J48 -> 0 | E42: =FAR!K48 -> 0
...

Sheet 공시IS
A1: 손익계산서
A2: 제 [ ](당) 기 [ ]년 [ ]월 [ ]일부터 [ ]년 [ ]월 [ ]일까지
A3: 제 [ ](전) 기 [ ]년 [ ]월 [ ]일부터 [ ]년 [ ]월 [ ]일까지
A4: =공시BS!A4 -> [회사명]
F5: (단위 : 원)
A6: 과 목 | B6: 주석 | C6: 당기 | E6: 전기
A7: Ⅰ.매출액 | D7: =SUM(C8:C11) -> 0 | F7: =SUM(E8:E11) -> 0 | H7: =D7=FAR!J118 -> TRUE | I7: =F7=FAR!K118 -> TRUE
A8: 제품매출 | C8: =FAR!J119 -> 0 | E8: =FAR!K119 -> 0
A9: 상품매출 | C9: =FAR!J120 -> 0 | E9: =FAR!K120 -> 0
A10: 기타매출 | C10: =FAR!J121 -> 0 | E10: =FAR!K121 -> 0
A11: 매출할인 | C11: =FAR!J122 -> 0 | E11: =FAR!K122 -> 0
A12: Ⅱ.매출원가 | D12: =D13+D22 -> 0 | F12: =F13+F22 -> 0 | H12: =D12=FAR!J123 -> TRUE | I12: =F12=FAR!K123 -> TRUE
A13: 1.상품매출원가 | D13: =SUM(C14:C21) -> 0 | F13: =SUM(E14:E21) -> 0 | H13: =D13=FAR!J124 -> TRUE | I13: =F13=FAR!K124 -> TRUE
A14: 기초상품재고액 | C14: =FAR!J125 -> 0 | E14: =FAR!K125 -> 0
A15: 당기상품매입액 | C15: =FAR!J126 -> 0 | E15: =FAR!K126 -> 0
A16: 타계정대체입고액(상품) | C16: =FAR!J127 -> 0 | E16: =FAR!K127 -> 0
A17: 매입할인(상품) | C17: =FAR!J128 -> 0 | E17: =FAR!K128 -> 0
A18: 타계정대체액(상품) | C18: =FAR!J129 -> 0 | E18: =FAR!K129 -> 0
A19: 재고자산평가손실 | C19: =FAR!J130 -> 0 | E19: =FAR!K130 -> 0
A20: 재고자산평가손실환입 | C20: =FAR!J131 -> 0 | E20: =FAR!K131 -> 0
A21: 기말상품재고액 | C21: =FAR!J132 -> 0 | E21: =FAR!K132 -> 0
A22: 2.제품매출원가 | D22: =SUM(C23:C27) -> 0 | F22: =SUM(E23:E27) -> 0 | H22: =D22=FAR!J133 -> TRUE | I22: =F22=FAR!K133 -> TRUE
A23: 기초제품재고액 | C23: =FAR!J134 -> 0 | E23: =FAR!K134 -> 0
A24: 당기제품제조원가 | C24: =FAR!J135 -> 0 | E24: =FAR!K135 -> 0
A25: 타계정에서대체액(제품) | C25: =FAR!J136 -> 0 | E25: =FAR!K136 -> 0
A26: 타계정으로대체액(제품) | C26: =FAR!J137 -> 0 | E26: =FAR!K137 -> 0
A27: 기말제품재고액 | C27: =FAR!J138 -> 0 | E27: =FAR!K138 -> 0
A28: Ⅲ.매출총이익 | D28: =D7-D12 -> 0 | F28: =F7-F12 -> 0 | H28: =D28=FAR!J139 -> TRUE | I28: =F28=FAR!K139 -> TRUE
A29: Ⅳ.판매비와관리비 | D29: =D30+D36 -> 0 | F29: =F30+F36 -> 0 | H29: =D29=FAR!J143 -> TRUE | I29: =F29=FAR!K143 -> TRUE
A30: 1.인건비 | D30: =SUM(C31:C35) -> 0 | F30: =SUM(E31:E35) -> 0 | H30: =D30=FAR!J144 -> TRUE | I30: =F30=FAR!K144 -> TRUE
A31: 급여 | C31: =FAR!J145 -> 0 | E31: =FAR!K145 -> 0
A32: 상여금 | C32: =FAR!J146 -> 0 | E32: =FAR!K146 -> 0
A33: 제수당 | C33: =FAR!J147 -> 0 | E33: =FAR!K147 -> 0
A34: 일용급여 | C34: =FAR!J148 -> 0 | E34: =FAR!K148 -> 0
A35: 퇴직급여 | C35: =FAR!J149 -> 0 | E35: =FAR!K149 -> 0
A36: 2.관리비 | D36: =SUM(C37:C57) -> 0 | F36: =SUM(E37:E57) -> 0 | H36: =D36=FAR!J150 -> TRUE | I36: =F36=FAR!K150 -> TRUE
A37: 복리후생비 | C37: =FAR!J151 -> 0 | E37: =FAR!K151 -> 0
A38: 여비교통비 | C38: =FAR!J152 -> 0 | E38: =FAR!K152 -> 0
A39: 접대비(기업업무추진비) | C39: =FAR!J153 -> 0 | E39: =FAR!K153 -> 0
A40: 통신비 | C40: =FAR!J154 -> 0 | E40: =FAR!K154 -> 0
...

Sheet 왜곡표시
M1: 회사로부터 제시받은 왜곡표시
B2: 회사명: | E2: [회사명] | H2: 작성자: | J2: 일자:
B3: 결산일: | H3: 검토자:
B5: Description | G5: BS | I5: IS | K5: 손익에 미치는 효과 | L5: Accep -ted | M5: Pass -ed
G6: Dr) | H6: Cr) | I6: Dr) | J6: Cr)
B62: 수정사항 효과 합계 | G62: =SUM(G7:G61) -> 0 | H62: =SUM(H7:H61) -> 0 | I62: =SUM(I7:I61) -> 0 | J62: =SUM(J7:J61) -> 0 | K62: =SUM(K7:K61) -> 0 | O62: =G62+I62=H62+J62 -> TRUE
K63: =FAR!I202-FAR!H202=K62 -> TRUE
F65: 왜곡표시 | G65: =G62+I62 -> 0 | H65: =H62+J62 -> 0
F66: 정산표 | G66: =FAR!H113 -> 0 | H66: =FAR!I113 -> 0
F67: diff | G67: =G65-G66 -> 0 | H67: =H65-H66 -> 0

Sheet FAR
D2: 계획단계 분석적절차 - Planning Analytical Review
F4: BDO
F5: CLIENT NAME | G5: [회사명] | K5: Preparer | L5: Reviewer | M5: Date | O5: 당기 기간(개월) | Q5: =IF(AND(ISNUMBER(P5),ISNUMBER(P6)),"","※ 기간(개월) 입력 필요 (Q5, Q6)") -> ※ 기간(개월) 입력 필요 (Q5, Q6)
F6: DOCUMENT NAME | G6: Planning Analytical Review | O6: 전기 기간(개월)
F7: PERIOD END | K7: Engagement Materiality | L7: Performance Materiality | M7: Currency
F8: DOCUMENT MANAGER REF | K8: =ROUND(G118*0.5%,-6) -> 0 | L8: =K8*75% -> 0 | M8: No Rounding
D10: 1. 재무상태표
G11: 당기(회사제시) | H11: Dr | I11: Cr | J11: 당기(검토후제시) | K11: 전기 | L11: Variance | N11: 중요성 양정기준 | O11: 유의중요성 x 75% | P11: 유의한 계정과목 | S11: 설명
J12: =G12 -> 0 | L12: 금액 | M12: % | N12: =K8 -> 0 | O12: =N12*75% -> 0 | P12: 양적 | Q12: 질적 | R12: 여부 결론
A13: 1 | D13: 재무상태표
B14: Assign | C14: 공시계정 | D14: Ⅰ.유동자산 | G14: =G15+G31 -> 0 | J14: =J15+J31 -> 0 | K14: =K15+K31 -> 0 | L14: =L15+L31 -> 0 | M14: =L14/K14 -> #DIV/0!
E15: 1.당좌자산 | G15: =SUM(G16:G30) -> 0 | J15: =SUM(J16:J30) -> 0 | K15: =SUM(K16:K30) -> 0 | L15: =SUM(L16:L30) -> 0 | M15: =L15/K15 -> #DIV/0! | N15: =G15/$N$12 -> #DIV/0! | O15: =G15/$O$12 -> #DIV/0! | P15: =IF(ABS(O15)>100%,"O","X") -> #DIV/0! | R15: =IF(P15="O","O",IF(Q15="O","O","X")) -> #DIV/0!
C16: 현금및현금성자산 | F16: 현금및현금성자산 | J16: =G16+H16-I16 -> 0 | L16: =J16-K16 -> 0 | M16: =L16/K16 -> #DIV/0! | N16: =G16/$N$12 -> #DIV/0! | O16: =G16/$O$12 -> #DIV/0! | P16: =IF(ABS(O16)>100%,"O","X") -> #DIV/0! | R16: =IF(P16="O","O",IF(Q16="O","O","X")) -> #DIV/0!
C17: 단기금융상품 | F17: 단기금융상품 | J17: =G17+H17-I17 -> 0 | L17: =J17-K17 -> 0 | M17: =L17/K17 -> #DIV/0! | N17: =G17/$N$12 -> #DIV/0! | O17: =G17/$O$12 -> #DIV/0! | P17: =IF(ABS(O17)>100%,"O","X") -> #DIV/0! | R17: =IF(P17="O","O",IF(Q17="O","O","X")) -> #DIV/0!
C18: 단기투자증권 | F18: 단기투자증권 | J18: =G18+H18-I18 -> 0 | L18: =J18-K18 -> 0 | M18: =L18/K18 -> #DIV/0! | N18: =G18/$N$12 -> #DIV/0! | O18: =G18/$O$12 -> #DIV/0! | P18: =IF(ABS(O18)>100%,"O","X") -> #DIV/0! | R18: =IF(P18="O","O",IF(Q18="O","O","X")) -> #DIV/0!
C19: 매출채권 | F19: 매출채권 | J19: =G19+H19-I19 -> 0 | L19: =J19-K19 -> 0 | M19: =L19/K19 -> #DIV/0! | N19: =G19/$N$12 -> #DIV/0! | O19: =G19/$O$12 -> #DIV/0! | P19: =IF(ABS(O19)>100%,"O","X") -> #DIV/0! | R19: =IF(P19="O","O",IF(Q19="O","O","X")) -> #DIV/0!
C20: 대손충당금(매출채권) | F20: 대손충당금(매출채권) | J20: =G20+H20-I20 -> 0 | L20: =J20-K20 -> 0 | M20: =L20/K20 -> #DIV/0! | N20: =G20/$N$12 -> #DIV/0! | O20: =G20/$O$12 -> #DIV/0! | P20: =IF(ABS(O20)>100%,"O","X") -> #DIV/0! | R20: =IF(P20="O","O",IF(Q20="O","O","X")) -> #DIV/0!
C21: 미수금 | F21: 미수금 | J21: =G21+H21-I21 -> 0 | L21: =J21-K21 -> 0 | M21: =L21/K21 -> #DIV/0! | N21: =G21/$N$12 -> #DIV/0! | O21: =G21/$O$12 -> #DIV/0! | P21: =IF(ABS(O21)>100%,"O","X") -> #DIV/0! | R21: =IF(P21="O","O",IF(Q21="O","O","X")) -> #DIV/0!
C22: 대손충당금(미수금) | F22: 대손충당금(미수금) | J22: =G22+H22-I22 -> 0 | L22: =J22-K22 -> 0 | M22: =L22/K22 -> #DIV/0! | N22: =G22/$N$12 -> #DIV/0! | O22: =G22/$O$12 -> #DIV/0! | P22: =IF(ABS(O22)>100%,"O","X") -> #DIV/0! | R22: =IF(P22="O","O",IF(Q22="O","O","X")) -> #DIV/0!
C23: 미수수익 | F23: 미수수익 | J23: =G23+H23-I23 -> 0 | L23: =J23-K23 -> 0 | M23: =L23/K23 -> #DIV/0! | N23: =G23/$N$12 -> #DIV/0! | O23: =G23/$O$12 -> #DIV/0! | P23: =IF(ABS(O23)>100%,"O","X") -> #DIV/0! | R23: =IF(P23="O","O",IF(Q23="O","O","X")) -> #DIV/0!
C24: 선급금 | F24: 선급금 | J24: =G24+H24-I24 -> 0 | L24: =J24-K24 -> 0 | M24: =L24/K24 -> #DIV/0! | N24: =G24/$N$12 -> #DIV/0! | O24: =G24/$O$12 -> #DIV/0! | P24: =IF(ABS(O24)>100%,"O","X") -> #DIV/0! | R24: =IF(P24="O","O",IF(Q24="O","O","X")) -> #DIV/0!
C25: 선급비용 | F25: 선급비용 | J25: =G25+H25-I25 -> 0 | L25: =J25-K25 -> 0 | M25: =L25/K25 -> #DIV/0! | N25: =G25/$N$12 -> #DIV/0! | O25: =G25/$O$12 -> #DIV/0! | P25: =IF(ABS(O25)>100%,"O","X") -> #DIV/0! | R25: =IF(P25="O","O",IF(Q25="O","O","X")) -> #DIV/0!
C26: 선납세금 | F26: 선납세금 | J26: =G26+H26-I26 -> 0 | L26: =J26-K26 -> 0 | M26: =L26/K26 -> #DIV/0! | N26: =G26/$N$12 -> #DIV/0! | O26: =G26/$O$12 -> #DIV/0! | P26: =IF(ABS(O26)>100%,"O","X") -> #DIV/0! | R26: =IF(P26="O","O",IF(Q26="O","O","X")) -> #DIV/0!
C27: 부가세대급금 | F27: 부가세대급금 | J27: =G27+H27-I27 -> 0 | L27: =J27-K27 -> 0 | M27: =L27/K27 -> #DIV/0! | N27: =G27/$N$12 -> #DIV/0! | O27: =G27/$O$12 -> #DIV/0! | P27: =IF(ABS(O27)>100%,"O","X") -> #DIV/0! | R27: =IF(P27="O","O",IF(Q27="O","O","X")) -> #DIV/0!
... C30: 기타당좌자산 | F30: 기타당좌자산 | J30: =G30+H30-I30 -> 0 | L30: =J30-K30 -> 0 | M30: =L30/K30 -> #DIV/0! | N30: =G30/$N$12 -> #DIV/0! | O30: =G30/$O$12 -> #DIV/0! | P30: =IF(ABS(O30)>100%,"O","X") -> #DIV/0! | R30: =IF(P30="O","O",IF(Q30="O","O","X")) -> #DIV/0!
E31: 2.재고자산 | G31: =SUM(G32:G40) -> 0 | J31: =SUM(J32:J40) -> 0 | K31: =SUM(K32:K40) -> 0 | L31: =SUM(L32:L40) -> 0 | M31: =L31/K31 -> #DIV/0! | N31: =G31/$N$12 -> #DIV/0! | O31: =G31/$O$12 -> #DIV/0! | P31: =IF(ABS(O31)>100%,"O","X") -> #DIV/0! | R31: =IF(P31="O","O",IF(Q31="O","O","X")) -> #DIV/0!
C32: 상품 | F32: 상품 | J32: =G32+H32-I32 -> 0 | L32: =J32-K32 -> 0 | M32: =L32/K32 -> #DIV/0! | N32: =G32/$N$12 -> #DIV/0! | O32: =G32/$O$12 -> #DIV/0! | P32: =IF(ABS(O32)>100%,"O","X") -> #DIV/0! | R32: =IF(P32="O","O",IF(Q32="O","O","X")) -> #DIV/0!
C33: 평가충당금(상품) | F33: 평가충당금(상품) | J33: =G33+H33-I33 -> 0 | L33: =J33-K33 -> 0 | M33: =L33/K33 -> #DIV/0! | N33: =G33/$N$12 -> #DIV/0! | O33: =G33/$O$12 -> #DIV/0! | P33: =IF(ABS(O33)>100%,"O","X") -> #DIV/0! | R33: =IF(P33="O","O",IF(Q33="O","O","X")) -> #DIV/0!
C34: 제품 | F34: 제품 | J34: =G34+H34-I34 -> 0 | L34: =J34-K34 -> 0 | M34: =L34/K34 -> #DIV/0! | N34: =G34/$N$12 -> #DIV/0! | O34: =G34/$O$12 -> #DIV/0! | P34: =IF(ABS(O34)>100%,"O","X") -> #DIV/0! | R34: =IF(P34="O","O",IF(Q34="O","O","X")) -> #DIV/0!
C35: 평가충당금(제품) | F35: 평가충당금(제품) | J35: =G35+H35-I35 -> 0 | L35: =J35-K35 -> 0 | M35: =L35/K35 -> #DIV/0! | N35: =G35/$N$12 -> #DIV/0! | O35: =G35/$O$12 -> #DIV/0! | P35: =IF(ABS(O35)>100%,"O","X") -> #DIV/0! | R35: =IF(P35="O","O",IF(Q35="O","O","X")) -> #DIV/0!
C36: 재공품 | F36: 재공품 | J36: =G36+H36-I36 -> 0 | L36: =J36-K36 -> 0 | M36: =L36/K36 -> #DIV/0! | N36: =G36/$N$12 -> #DIV/0! | O36: =G36/$O$12 -> #DIV/0! | P36: =IF(ABS(O36)>100%,"O","X") -> #DIV/0! | R36: =IF(P36="O","O",IF(Q36="O","O","X")) -> #DIV/0!
C37: 평가충당금(재공품) | F37: 평가충당금(재공품) | J37: =G37+H37-I37 -> 0 | L37: =J37-K37 -> 0 | M37: =L37/K37 -> #DIV/0! | N37: =G37/$N$12 -> #DIV/0! | O37: =G37/$O$12 -> #DIV/0! | P37: =IF(ABS(O37)>100%,"O","X") -> #DIV/0! | R37: =IF(P37="O","O",IF(Q37="O","O","X")) -> #DIV/0!
C38: 원재료 | F38: 원재료 | J38: =G38+H38-I38 -> 0 | L38: =J38-K38 -> 0 | M38: =L38/K38 -> #DIV/0! | N38: =G38/$N$12 -> #DIV/0! | O38: =G38/$O$12 -> #DIV/0! | P38: =IF(ABS(O38)>100%,"O","X") -> #DIV/0! | R38: =IF(P38="O","O",IF(Q38="O","O","X")) -> #DIV/0!
C39: 평가충당금(원재료) | F39: 평가충당금(원재료) | J39: =G39+H39-I39 -> 0 | L39: =J39-K39 -> 0 | M39: =L39/K39 -> #DIV/0! | N39: =G39/$N$12 -> #DIV/0! | O39: =G39/$O$12 -> #DIV/0! | P39: =IF(ABS(O39)>100%,"O","X") -> #DIV/0! | R39: =IF(P39="O","O",IF(Q39="O","O","X")) -> #DIV/0!
C40: 기타재고자산 | F40: 기타재고자산 | J40: =G40+H40-I40 -> 0 | L40: =J40-K40 -> 0 | M40: =L40/K40 -> #DIV/0! | N40: =G40/$N$12 -> #DIV/0! | O40: =G40/$O$12 -> #DIV/0! | P40: =IF(ABS(O40)>100%,"O","X") -> #DIV/0! | R40: =IF(P40="O","O",IF(Q40="O","O","X")) -> #DIV/0!
D41: Ⅱ.비유동자산 | G41: =G42+G50+G66+G71 -> 0 | J41: =J42+J50+J66+J71 -> 0 | K41: =K42+K50+K66+K71 -> 0 | L41: =L42+L50+L66+L71 -> 0 | M41: =L41/K41 -> #DIV/0! | N41: =G41/$N$12 -> #DIV/0! | O41: =G41/$O$12 -> #DIV/0! | P41: =IF(ABS(O41)>100%,"O","X") -> #DIV/0! | R41: =IF(P41="O","O",IF(Q41="O","O","X")) -> #DIV/0!
E42: 1.투자자산 | G42: =SUM(G43:G49) -> 0 | J42: =SUM(J43:J49) -> 0 | K42: =SUM(K43:K49) -> 0 | L42: =SUM(L43:L49) -> 0 | M42: =L42/K42 -> #DIV/0! | N42: =G42/$N$12 -> #DIV/0! | O42: =G42/$O$12 -> #DIV/0! | P42: =IF(ABS(O42)>100%,"O","X") -> #DIV/0! | R42: =IF(P42="O","O",IF(Q42="O","O","X")) -> #DIV/0!
C43: 장기금융상품 | F43: 장기금융상품 | J43: =G43+H43-I43 -> 0 | L43: =J43-K43 -> 0 | M43: =L43/K43 -> #DIV/0! | N43: =G43/$N$12 -> #DIV/0! | O43: =G43/$O$12 -> #DIV/0! | P43: =IF(ABS(O43)>100%,"O","X") -> #DIV/0! | R43: =IF(P43="O","O",IF(Q43="O","O","X")) -> #DIV/0!
C44: 장기투자증권 | F44: 장기투자증권 | J44: =G44+H44-I44 -> 0 | L44: =J44-K44 -> 0 | M44: =L44/K44 -> #DIV/0! | N44: =G44/$N$12 -> #DIV/0! | O44: =G44/$O$12 -> #DIV/0! | P44: =IF(ABS(O44)>100%,"O","X") -> #DIV/0! | R44: =IF(P44="O","O",IF(Q44="O","O","X")) -> #DIV/0!
C45: 지분법적용투자주식 | F45: 지분법적용투자주식 | J45: =G45+H45-I45 -> 0 | L45: =J45-K45 -> 0 | M45: =L45/K45 -> #DIV/0! | N45: =G45/$N$12 -> #DIV/0! | O45: =G45/$O$12 -> #DIV/0! | P45: =IF(ABS(O45)>100%,"O","X") -> #DIV/0! | R45: =IF(P45="O","O",IF(Q45="O","O","X")) -> #DIV/0!
...
